[2022-04-25 02:32:15,064] {taskinstance.py:1037} INFO - Dependencies all met for <TaskInstance: upload_to_drive.upload_file manual__2022-04-25T02:32:09.941110+00:00 [queued]>
[2022-04-25 02:32:15,154] {taskinstance.py:1037} INFO - Dependencies all met for <TaskInstance: upload_to_drive.upload_file manual__2022-04-25T02:32:09.941110+00:00 [queued]>
[2022-04-25 02:32:15,155] {taskinstance.py:1243} INFO - 
--------------------------------------------------------------------------------
[2022-04-25 02:32:15,156] {taskinstance.py:1244} INFO - Starting attempt 1 of 1
[2022-04-25 02:32:15,158] {taskinstance.py:1245} INFO - 
--------------------------------------------------------------------------------
[2022-04-25 02:32:15,220] {taskinstance.py:1264} INFO - Executing <Task(GoogleDriveOperator): upload_file> on 2022-04-25 02:32:09.941110+00:00
[2022-04-25 02:32:15,234] {standard_task_runner.py:52} INFO - Started process 10446 to run task
[2022-04-25 02:32:15,256] {standard_task_runner.py:76} INFO - Running: ['***', 'tasks', 'run', 'upload_to_drive', 'upload_file', 'manual__2022-04-25T02:32:09.941110+00:00', '--job-id', '85', '--raw', '--subdir', 'DAGS_FOLDER/upload_to_drive_dag.py', '--cfg-path', '/tmp/tmp15uerdb4', '--error-file', '/tmp/tmpqfulgc4l']
[2022-04-25 02:32:15,260] {standard_task_runner.py:77} INFO - Job 85: Subtask upload_file
[2022-04-25 02:32:15,380] {logging_mixin.py:109} INFO - Running <TaskInstance: upload_to_drive.upload_file manual__2022-04-25T02:32:09.941110+00:00 [running]> on host e37e04a9d1d5
[2022-04-25 02:32:15,542] {taskinstance.py:1431} INFO - Exporting the following env vars:
AIRFLOW_CTX_DAG_OWNER=***
AIRFLOW_CTX_DAG_ID=upload_to_drive
AIRFLOW_CTX_TASK_ID=upload_file
AIRFLOW_CTX_EXECUTION_DATE=2022-04-25T02:32:09.941110+00:00
AIRFLOW_CTX_DAG_RUN_ID=manual__2022-04-25T02:32:09.941110+00:00
[2022-04-25 02:32:15,803] {google_drive_operator.py:60} INFO - Uploading file: tmp/prueba_drive.txt
[2022-04-25 02:32:16,023] {credentials_provider.py:312} INFO - Getting connection using `google.auth.default()` since no key file is defined for hook.
[2022-04-25 02:32:19,071] {_metadata.py:104} WARNING - Compute Engine Metadata server unavailable on attempt 1 of 3. Reason: timed out
[2022-04-25 02:32:22,083] {_metadata.py:104} WARNING - Compute Engine Metadata server unavailable on attempt 2 of 3. Reason: timed out
[2022-04-25 02:32:22,219] {_metadata.py:104} WARNING - Compute Engine Metadata server unavailable on attempt 3 of 3. Reason: [Errno 111] Connection refused
[2022-04-25 02:32:22,220] {_default.py:287} WARNING - Authentication failed using Compute Engine authentication due to unavailable metadata server.
[2022-04-25 02:32:22,221] {taskinstance.py:1718} ERROR - Task failed with exception
Traceback (most recent call last):
  File "/home/airflow/.local/lib/python3.7/site-packages/airflow/models/taskinstance.py", line 1334, in _run_raw_task
    self._execute_task_with_callbacks(context)
  File "/home/airflow/.local/lib/python3.7/site-packages/airflow/models/taskinstance.py", line 1460, in _execute_task_with_callbacks
    result = self._execute_task(context, self.task)
  File "/home/airflow/.local/lib/python3.7/site-packages/airflow/models/taskinstance.py", line 1516, in _execute_task
    result = execute_callable(context=context)
  File "/opt/airflow/plugins/google_drive_operator.py", line 66, in execute
    remote_location=os.path.join(self.drive_folder, file_name)
  File "/home/airflow/.local/lib/python3.7/site-packages/airflow/providers/google/suite/hooks/drive.py", line 192, in upload_file
    service = self.get_conn()
  File "/home/airflow/.local/lib/python3.7/site-packages/airflow/providers/google/suite/hooks/drive.py", line 69, in get_conn
    http_authorized = self._authorize()
  File "/home/airflow/.local/lib/python3.7/site-packages/airflow/providers/google/common/hooks/base_google.py", line 288, in _authorize
    credentials = self._get_credentials()
  File "/home/airflow/.local/lib/python3.7/site-packages/airflow/providers/google/common/hooks/base_google.py", line 259, in _get_credentials
    credentials, _ = self._get_credentials_and_project_id()
  File "/home/airflow/.local/lib/python3.7/site-packages/airflow/providers/google/common/hooks/base_google.py", line 245, in _get_credentials_and_project_id
    delegates=delegates,
  File "/home/airflow/.local/lib/python3.7/site-packages/airflow/providers/google/cloud/utils/credentials_provider.py", line 321, in get_credentials_and_project_id
    return _CredentialProvider(*args, **kwargs).get_credentials_and_project()
  File "/home/airflow/.local/lib/python3.7/site-packages/airflow/providers/google/cloud/utils/credentials_provider.py", line 229, in get_credentials_and_project
    credentials, project_id = self._get_credentials_using_adc()
  File "/home/airflow/.local/lib/python3.7/site-packages/airflow/providers/google/cloud/utils/credentials_provider.py", line 307, in _get_credentials_using_adc
    credentials, project_id = google.auth.default(scopes=self.scopes)
  File "/home/airflow/.local/lib/python3.7/site-packages/google/auth/_default.py", line 488, in default
    raise exceptions.DefaultCredentialsError(_HELP_MESSAGE)
google.auth.exceptions.DefaultCredentialsError: Could not automatically determine credentials. Please set GOOGLE_APPLICATION_CREDENTIALS or explicitly create credentials and re-run the application. For more information, please see https://cloud.google.com/docs/authentication/getting-started
[2022-04-25 02:32:22,247] {taskinstance.py:1282} INFO - Marking task as FAILED. dag_id=upload_to_drive, task_id=upload_file, execution_date=20220425T023209, start_date=20220425T023215, end_date=20220425T023222
[2022-04-25 02:32:22,392] {standard_task_runner.py:92} ERROR - Failed to execute job 85 for task upload_file
Traceback (most recent call last):
  File "/home/airflow/.local/lib/python3.7/site-packages/airflow/task/task_runner/standard_task_runner.py", line 85, in _start_by_fork
    args.func(args, dag=self.dag)
  File "/home/airflow/.local/lib/python3.7/site-packages/airflow/cli/cli_parser.py", line 48, in command
    return func(*args, **kwargs)
  File "/home/airflow/.local/lib/python3.7/site-packages/airflow/utils/cli.py", line 92, in wrapper
    return f(*args, **kwargs)
  File "/home/airflow/.local/lib/python3.7/site-packages/airflow/cli/commands/task_command.py", line 298, in task_run
    _run_task_by_selected_method(args, dag, ti)
  File "/home/airflow/.local/lib/python3.7/site-packages/airflow/cli/commands/task_command.py", line 107, in _run_task_by_selected_method
    _run_raw_task(args, ti)
  File "/home/airflow/.local/lib/python3.7/site-packages/airflow/cli/commands/task_command.py", line 184, in _run_raw_task
    error_file=args.error_file,
  File "/home/airflow/.local/lib/python3.7/site-packages/airflow/utils/session.py", line 70, in wrapper
    return func(*args, session=session, **kwargs)
  File "/home/airflow/.local/lib/python3.7/site-packages/airflow/models/taskinstance.py", line 1334, in _run_raw_task
    self._execute_task_with_callbacks(context)
  File "/home/airflow/.local/lib/python3.7/site-packages/airflow/models/taskinstance.py", line 1460, in _execute_task_with_callbacks
    result = self._execute_task(context, self.task)
  File "/home/airflow/.local/lib/python3.7/site-packages/airflow/models/taskinstance.py", line 1516, in _execute_task
    result = execute_callable(context=context)
  File "/opt/airflow/plugins/google_drive_operator.py", line 66, in execute
    remote_location=os.path.join(self.drive_folder, file_name)
  File "/home/airflow/.local/lib/python3.7/site-packages/airflow/providers/google/suite/hooks/drive.py", line 192, in upload_file
    service = self.get_conn()
  File "/home/airflow/.local/lib/python3.7/site-packages/airflow/providers/google/suite/hooks/drive.py", line 69, in get_conn
    http_authorized = self._authorize()
  File "/home/airflow/.local/lib/python3.7/site-packages/airflow/providers/google/common/hooks/base_google.py", line 288, in _authorize
    credentials = self._get_credentials()
  File "/home/airflow/.local/lib/python3.7/site-packages/airflow/providers/google/common/hooks/base_google.py", line 259, in _get_credentials
    credentials, _ = self._get_credentials_and_project_id()
  File "/home/airflow/.local/lib/python3.7/site-packages/airflow/providers/google/common/hooks/base_google.py", line 245, in _get_credentials_and_project_id
    delegates=delegates,
  File "/home/airflow/.local/lib/python3.7/site-packages/airflow/providers/google/cloud/utils/credentials_provider.py", line 321, in get_credentials_and_project_id
    return _CredentialProvider(*args, **kwargs).get_credentials_and_project()
  File "/home/airflow/.local/lib/python3.7/site-packages/airflow/providers/google/cloud/utils/credentials_provider.py", line 229, in get_credentials_and_project
    credentials, project_id = self._get_credentials_using_adc()
  File "/home/airflow/.local/lib/python3.7/site-packages/airflow/providers/google/cloud/utils/credentials_provider.py", line 307, in _get_credentials_using_adc
    credentials, project_id = google.auth.default(scopes=self.scopes)
  File "/home/airflow/.local/lib/python3.7/site-packages/google/auth/_default.py", line 488, in default
    raise exceptions.DefaultCredentialsError(_HELP_MESSAGE)
google.auth.exceptions.DefaultCredentialsError: Could not automatically determine credentials. Please set GOOGLE_APPLICATION_CREDENTIALS or explicitly create credentials and re-run the application. For more information, please see https://cloud.google.com/docs/authentication/getting-started
[2022-04-25 02:32:22,426] {local_task_job.py:154} INFO - Task exited with return code 1
[2022-04-25 02:32:22,460] {local_task_job.py:264} INFO - 0 downstream tasks scheduled from follow-on schedule check
