[2022-04-24 21:28:32,288] {taskinstance.py:1037} INFO - Dependencies all met for <TaskInstance: upload_to_drive.create_file manual__2022-04-24T21:28:27.950221+00:00 [queued]>
[2022-04-24 21:28:32,311] {taskinstance.py:1037} INFO - Dependencies all met for <TaskInstance: upload_to_drive.create_file manual__2022-04-24T21:28:27.950221+00:00 [queued]>
[2022-04-24 21:28:32,312] {taskinstance.py:1243} INFO - 
--------------------------------------------------------------------------------
[2022-04-24 21:28:32,313] {taskinstance.py:1244} INFO - Starting attempt 1 of 1
[2022-04-24 21:28:32,314] {taskinstance.py:1245} INFO - 
--------------------------------------------------------------------------------
[2022-04-24 21:28:32,330] {taskinstance.py:1264} INFO - Executing <Task(BashOperator): create_file> on 2022-04-24 21:28:27.950221+00:00
[2022-04-24 21:28:32,336] {standard_task_runner.py:52} INFO - Started process 587 to run task
[2022-04-24 21:28:32,352] {standard_task_runner.py:76} INFO - Running: ['***', 'tasks', 'run', 'upload_to_drive', 'create_file', 'manual__2022-04-24T21:28:27.950221+00:00', '--job-id', '64', '--raw', '--subdir', 'DAGS_FOLDER/upload_to_drive_dag.py', '--cfg-path', '/tmp/tmpqo9km580', '--error-file', '/tmp/tmpyuw6__81']
[2022-04-24 21:28:32,354] {standard_task_runner.py:77} INFO - Job 64: Subtask create_file
[2022-04-24 21:28:32,459] {logging_mixin.py:109} INFO - Running <TaskInstance: upload_to_drive.create_file manual__2022-04-24T21:28:27.950221+00:00 [running]> on host e37e04a9d1d5
[2022-04-24 21:28:32,567] {taskinstance.py:1431} INFO - Exporting the following env vars:
AIRFLOW_CTX_DAG_OWNER=***
AIRFLOW_CTX_DAG_ID=upload_to_drive
AIRFLOW_CTX_TASK_ID=create_file
AIRFLOW_CTX_EXECUTION_DATE=2022-04-24T21:28:27.950221+00:00
AIRFLOW_CTX_DAG_RUN_ID=manual__2022-04-24T21:28:27.950221+00:00
[2022-04-24 21:28:32,572] {subprocess.py:62} INFO - Tmp dir root location: 
 /tmp
[2022-04-24 21:28:32,574] {subprocess.py:74} INFO - Running command: ['bash', '-c', 'echo file created on 2022-04-24. > ${AIRFLOW_HOME}/tmp/my_file_2022-04-24.txt']
[2022-04-24 21:28:32,665] {subprocess.py:85} INFO - Output:
[2022-04-24 21:28:32,741] {subprocess.py:89} INFO - bash: /opt/***/tmp/my_file_2022-04-24.txt: No such file or directory
[2022-04-24 21:28:32,754] {subprocess.py:93} INFO - Command exited with return code 1
[2022-04-24 21:28:32,787] {taskinstance.py:1718} ERROR - Task failed with exception
Traceback (most recent call last):
  File "/home/airflow/.local/lib/python3.7/site-packages/airflow/models/taskinstance.py", line 1334, in _run_raw_task
    self._execute_task_with_callbacks(context)
  File "/home/airflow/.local/lib/python3.7/site-packages/airflow/models/taskinstance.py", line 1460, in _execute_task_with_callbacks
    result = self._execute_task(context, self.task)
  File "/home/airflow/.local/lib/python3.7/site-packages/airflow/models/taskinstance.py", line 1516, in _execute_task
    result = execute_callable(context=context)
  File "/home/airflow/.local/lib/python3.7/site-packages/airflow/operators/bash.py", line 188, in execute
    f'Bash command failed. The command returned a non-zero exit code {result.exit_code}.'
airflow.exceptions.AirflowException: Bash command failed. The command returned a non-zero exit code 1.
[2022-04-24 21:28:32,827] {taskinstance.py:1282} INFO - Marking task as FAILED. dag_id=upload_to_drive, task_id=create_file, execution_date=20220424T212827, start_date=20220424T212832, end_date=20220424T212832
[2022-04-24 21:28:32,892] {standard_task_runner.py:92} ERROR - Failed to execute job 64 for task create_file
Traceback (most recent call last):
  File "/home/airflow/.local/lib/python3.7/site-packages/airflow/task/task_runner/standard_task_runner.py", line 85, in _start_by_fork
    args.func(args, dag=self.dag)
  File "/home/airflow/.local/lib/python3.7/site-packages/airflow/cli/cli_parser.py", line 48, in command
    return func(*args, **kwargs)
  File "/home/airflow/.local/lib/python3.7/site-packages/airflow/utils/cli.py", line 92, in wrapper
    return f(*args, **kwargs)
  File "/home/airflow/.local/lib/python3.7/site-packages/airflow/cli/commands/task_command.py", line 298, in task_run
    _run_task_by_selected_method(args, dag, ti)
  File "/home/airflow/.local/lib/python3.7/site-packages/airflow/cli/commands/task_command.py", line 107, in _run_task_by_selected_method
    _run_raw_task(args, ti)
  File "/home/airflow/.local/lib/python3.7/site-packages/airflow/cli/commands/task_command.py", line 184, in _run_raw_task
    error_file=args.error_file,
  File "/home/airflow/.local/lib/python3.7/site-packages/airflow/utils/session.py", line 70, in wrapper
    return func(*args, session=session, **kwargs)
  File "/home/airflow/.local/lib/python3.7/site-packages/airflow/models/taskinstance.py", line 1334, in _run_raw_task
    self._execute_task_with_callbacks(context)
  File "/home/airflow/.local/lib/python3.7/site-packages/airflow/models/taskinstance.py", line 1460, in _execute_task_with_callbacks
    result = self._execute_task(context, self.task)
  File "/home/airflow/.local/lib/python3.7/site-packages/airflow/models/taskinstance.py", line 1516, in _execute_task
    result = execute_callable(context=context)
  File "/home/airflow/.local/lib/python3.7/site-packages/airflow/operators/bash.py", line 188, in execute
    f'Bash command failed. The command returned a non-zero exit code {result.exit_code}.'
airflow.exceptions.AirflowException: Bash command failed. The command returned a non-zero exit code 1.
[2022-04-24 21:28:32,937] {local_task_job.py:154} INFO - Task exited with return code 1
[2022-04-24 21:28:33,003] {local_task_job.py:264} INFO - 0 downstream tasks scheduled from follow-on schedule check
