[2022-04-23 21:21:04,255] {taskinstance.py:1037} INFO - Dependencies all met for <TaskInstance: upload_to_drive.create_file scheduled__2022-04-21T00:00:00+00:00 [queued]>
[2022-04-23 21:21:04,404] {taskinstance.py:1037} INFO - Dependencies all met for <TaskInstance: upload_to_drive.create_file scheduled__2022-04-21T00:00:00+00:00 [queued]>
[2022-04-23 21:21:04,407] {taskinstance.py:1243} INFO - 
--------------------------------------------------------------------------------
[2022-04-23 21:21:04,410] {taskinstance.py:1244} INFO - Starting attempt 1 of 1
[2022-04-23 21:21:04,414] {taskinstance.py:1245} INFO - 
--------------------------------------------------------------------------------
[2022-04-23 21:21:04,564] {taskinstance.py:1264} INFO - Executing <Task(BashOperator): create_file> on 2022-04-21 00:00:00+00:00
[2022-04-23 21:21:04,613] {standard_task_runner.py:76} INFO - Running: ['***', 'tasks', 'run', 'upload_to_drive', 'create_file', 'scheduled__2022-04-21T00:00:00+00:00', '--job-id', '24', '--raw', '--subdir', 'DAGS_FOLDER/upload_to_drive_dag.py', '--cfg-path', '/tmp/tmpyx08dk_t', '--error-file', '/tmp/tmpymc_qkqm']
[2022-04-23 21:21:04,600] {standard_task_runner.py:52} INFO - Started process 139 to run task
[2022-04-23 21:21:04,646] {standard_task_runner.py:77} INFO - Job 24: Subtask create_file
[2022-04-23 21:21:05,267] {logging_mixin.py:109} INFO - Running <TaskInstance: upload_to_drive.create_file scheduled__2022-04-21T00:00:00+00:00 [running]> on host 5084c36291e5
[2022-04-23 21:21:10,621] {taskinstance.py:1431} INFO - Exporting the following env vars:
AIRFLOW_CTX_DAG_OWNER=***
AIRFLOW_CTX_DAG_ID=upload_to_drive
AIRFLOW_CTX_TASK_ID=create_file
AIRFLOW_CTX_EXECUTION_DATE=2022-04-21T00:00:00+00:00
AIRFLOW_CTX_DAG_RUN_ID=scheduled__2022-04-21T00:00:00+00:00
[2022-04-23 21:21:10,631] {subprocess.py:62} INFO - Tmp dir root location: 
 /tmp
[2022-04-23 21:21:10,635] {subprocess.py:74} INFO - Running command: ['bash', '-c', 'echo file created on 2022-04-21. > ${AIRFLOW_HOME}/tmp/my_file_2022-04-21.txt']
[2022-04-23 21:21:10,897] {subprocess.py:85} INFO - Output:
[2022-04-23 21:21:10,956] {subprocess.py:89} INFO - bash: /opt/***/tmp/my_file_2022-04-21.txt: No such file or directory
[2022-04-23 21:21:10,960] {subprocess.py:93} INFO - Command exited with return code 1
[2022-04-23 21:21:11,065] {taskinstance.py:1718} ERROR - Task failed with exception
Traceback (most recent call last):
  File "/home/airflow/.local/lib/python3.7/site-packages/airflow/models/taskinstance.py", line 1334, in _run_raw_task
    self._execute_task_with_callbacks(context)
  File "/home/airflow/.local/lib/python3.7/site-packages/airflow/models/taskinstance.py", line 1460, in _execute_task_with_callbacks
    result = self._execute_task(context, self.task)
  File "/home/airflow/.local/lib/python3.7/site-packages/airflow/models/taskinstance.py", line 1516, in _execute_task
    result = execute_callable(context=context)
  File "/home/airflow/.local/lib/python3.7/site-packages/airflow/operators/bash.py", line 188, in execute
    f'Bash command failed. The command returned a non-zero exit code {result.exit_code}.'
airflow.exceptions.AirflowException: Bash command failed. The command returned a non-zero exit code 1.
[2022-04-23 21:21:11,138] {taskinstance.py:1282} INFO - Marking task as FAILED. dag_id=upload_to_drive, task_id=create_file, execution_date=20220421T000000, start_date=20220423T212104, end_date=20220423T212111
[2022-04-23 21:21:11,215] {standard_task_runner.py:92} ERROR - Failed to execute job 24 for task create_file
Traceback (most recent call last):
  File "/home/airflow/.local/lib/python3.7/site-packages/airflow/task/task_runner/standard_task_runner.py", line 85, in _start_by_fork
    args.func(args, dag=self.dag)
  File "/home/airflow/.local/lib/python3.7/site-packages/airflow/cli/cli_parser.py", line 48, in command
    return func(*args, **kwargs)
  File "/home/airflow/.local/lib/python3.7/site-packages/airflow/utils/cli.py", line 92, in wrapper
    return f(*args, **kwargs)
  File "/home/airflow/.local/lib/python3.7/site-packages/airflow/cli/commands/task_command.py", line 298, in task_run
    _run_task_by_selected_method(args, dag, ti)
  File "/home/airflow/.local/lib/python3.7/site-packages/airflow/cli/commands/task_command.py", line 107, in _run_task_by_selected_method
    _run_raw_task(args, ti)
  File "/home/airflow/.local/lib/python3.7/site-packages/airflow/cli/commands/task_command.py", line 184, in _run_raw_task
    error_file=args.error_file,
  File "/home/airflow/.local/lib/python3.7/site-packages/airflow/utils/session.py", line 70, in wrapper
    return func(*args, session=session, **kwargs)
  File "/home/airflow/.local/lib/python3.7/site-packages/airflow/models/taskinstance.py", line 1334, in _run_raw_task
    self._execute_task_with_callbacks(context)
  File "/home/airflow/.local/lib/python3.7/site-packages/airflow/models/taskinstance.py", line 1460, in _execute_task_with_callbacks
    result = self._execute_task(context, self.task)
  File "/home/airflow/.local/lib/python3.7/site-packages/airflow/models/taskinstance.py", line 1516, in _execute_task
    result = execute_callable(context=context)
  File "/home/airflow/.local/lib/python3.7/site-packages/airflow/operators/bash.py", line 188, in execute
    f'Bash command failed. The command returned a non-zero exit code {result.exit_code}.'
airflow.exceptions.AirflowException: Bash command failed. The command returned a non-zero exit code 1.
[2022-04-23 21:21:11,346] {local_task_job.py:154} INFO - Task exited with return code 1
[2022-04-23 21:21:11,495] {local_task_job.py:264} INFO - 0 downstream tasks scheduled from follow-on schedule check
