[2022-04-24 16:48:47,653] {taskinstance.py:1037} INFO - Dependencies all met for <TaskInstance: upload_to_drive.upload_file scheduled__2022-04-23T00:00:00+00:00 [queued]>
[2022-04-24 16:48:47,725] {taskinstance.py:1037} INFO - Dependencies all met for <TaskInstance: upload_to_drive.upload_file scheduled__2022-04-23T00:00:00+00:00 [queued]>
[2022-04-24 16:48:47,733] {taskinstance.py:1243} INFO - 
--------------------------------------------------------------------------------
[2022-04-24 16:48:47,734] {taskinstance.py:1244} INFO - Starting attempt 1 of 1
[2022-04-24 16:48:47,735] {taskinstance.py:1245} INFO - 
--------------------------------------------------------------------------------
[2022-04-24 16:48:48,012] {taskinstance.py:1264} INFO - Executing <Task(GoogleDriveOperator): upload_file> on 2022-04-23 00:00:00+00:00
[2022-04-24 16:48:48,036] {standard_task_runner.py:52} INFO - Started process 103 to run task
[2022-04-24 16:48:48,067] {standard_task_runner.py:76} INFO - Running: ['***', 'tasks', 'run', 'upload_to_drive', 'upload_file', 'scheduled__2022-04-23T00:00:00+00:00', '--job-id', '60', '--raw', '--subdir', 'DAGS_FOLDER/upload_to_drive_dag.py', '--cfg-path', '/tmp/tmpl1f_p6on', '--error-file', '/tmp/tmpa2gvbg4g']
[2022-04-24 16:48:48,070] {standard_task_runner.py:77} INFO - Job 60: Subtask upload_file
[2022-04-24 16:48:48,772] {logging_mixin.py:109} INFO - Running <TaskInstance: upload_to_drive.upload_file scheduled__2022-04-23T00:00:00+00:00 [running]> on host e37e04a9d1d5
[2022-04-24 16:48:51,484] {taskinstance.py:1431} INFO - Exporting the following env vars:
AIRFLOW_CTX_DAG_OWNER=***
AIRFLOW_CTX_DAG_ID=upload_to_drive
AIRFLOW_CTX_TASK_ID=upload_file
AIRFLOW_CTX_EXECUTION_DATE=2022-04-23T00:00:00+00:00
AIRFLOW_CTX_DAG_RUN_ID=scheduled__2022-04-23T00:00:00+00:00
[2022-04-24 16:48:52,432] {taskinstance.py:1718} ERROR - Task failed with exception
Traceback (most recent call last):
  File "/home/airflow/.local/lib/python3.7/site-packages/airflow/models/taskinstance.py", line 1334, in _run_raw_task
    self._execute_task_with_callbacks(context)
  File "/home/airflow/.local/lib/python3.7/site-packages/airflow/models/taskinstance.py", line 1460, in _execute_task_with_callbacks
    result = self._execute_task(context, self.task)
  File "/home/airflow/.local/lib/python3.7/site-packages/airflow/models/taskinstance.py", line 1516, in _execute_task
    result = execute_callable(context=context)
  File "/opt/airflow/plugins/google_drive_operator.py", line 57, in execute
    impersonation_chain=self.impersonation_chain
  File "/home/airflow/.local/lib/python3.7/site-packages/airflow/providers/google/suite/hooks/drive.py", line 58, in __init__
    impersonation_chain=impersonation_chain,
  File "/home/airflow/.local/lib/python3.7/site-packages/airflow/providers/google/common/hooks/base_google.py", line 217, in __init__
    self.extras = self.get_connection(self.gcp_conn_id).extra_dejson  # type: Dict
  File "/home/airflow/.local/lib/python3.7/site-packages/airflow/hooks/base.py", line 68, in get_connection
    conn = Connection.get_connection_from_secrets(conn_id)
  File "/home/airflow/.local/lib/python3.7/site-packages/airflow/models/connection.py", line 410, in get_connection_from_secrets
    raise AirflowNotFoundException(f"The conn_id `{conn_id}` isn't defined")
airflow.exceptions.AirflowNotFoundException: The conn_id `***-to-drive` isn't defined
[2022-04-24 16:48:52,494] {taskinstance.py:1282} INFO - Marking task as FAILED. dag_id=upload_to_drive, task_id=upload_file, execution_date=20220423T000000, start_date=20220424T164847, end_date=20220424T164852
[2022-04-24 16:48:52,674] {standard_task_runner.py:92} ERROR - Failed to execute job 60 for task upload_file
Traceback (most recent call last):
  File "/home/airflow/.local/lib/python3.7/site-packages/airflow/task/task_runner/standard_task_runner.py", line 85, in _start_by_fork
    args.func(args, dag=self.dag)
  File "/home/airflow/.local/lib/python3.7/site-packages/airflow/cli/cli_parser.py", line 48, in command
    return func(*args, **kwargs)
  File "/home/airflow/.local/lib/python3.7/site-packages/airflow/utils/cli.py", line 92, in wrapper
    return f(*args, **kwargs)
  File "/home/airflow/.local/lib/python3.7/site-packages/airflow/cli/commands/task_command.py", line 298, in task_run
    _run_task_by_selected_method(args, dag, ti)
  File "/home/airflow/.local/lib/python3.7/site-packages/airflow/cli/commands/task_command.py", line 107, in _run_task_by_selected_method
    _run_raw_task(args, ti)
  File "/home/airflow/.local/lib/python3.7/site-packages/airflow/cli/commands/task_command.py", line 184, in _run_raw_task
    error_file=args.error_file,
  File "/home/airflow/.local/lib/python3.7/site-packages/airflow/utils/session.py", line 70, in wrapper
    return func(*args, session=session, **kwargs)
  File "/home/airflow/.local/lib/python3.7/site-packages/airflow/models/taskinstance.py", line 1334, in _run_raw_task
    self._execute_task_with_callbacks(context)
  File "/home/airflow/.local/lib/python3.7/site-packages/airflow/models/taskinstance.py", line 1460, in _execute_task_with_callbacks
    result = self._execute_task(context, self.task)
  File "/home/airflow/.local/lib/python3.7/site-packages/airflow/models/taskinstance.py", line 1516, in _execute_task
    result = execute_callable(context=context)
  File "/opt/airflow/plugins/google_drive_operator.py", line 57, in execute
    impersonation_chain=self.impersonation_chain
  File "/home/airflow/.local/lib/python3.7/site-packages/airflow/providers/google/suite/hooks/drive.py", line 58, in __init__
    impersonation_chain=impersonation_chain,
  File "/home/airflow/.local/lib/python3.7/site-packages/airflow/providers/google/common/hooks/base_google.py", line 217, in __init__
    self.extras = self.get_connection(self.gcp_conn_id).extra_dejson  # type: Dict
  File "/home/airflow/.local/lib/python3.7/site-packages/airflow/hooks/base.py", line 68, in get_connection
    conn = Connection.get_connection_from_secrets(conn_id)
  File "/home/airflow/.local/lib/python3.7/site-packages/airflow/models/connection.py", line 410, in get_connection_from_secrets
    raise AirflowNotFoundException(f"The conn_id `{conn_id}` isn't defined")
airflow.exceptions.AirflowNotFoundException: The conn_id `***-to-drive` isn't defined
[2022-04-24 16:48:52,805] {local_task_job.py:154} INFO - Task exited with return code 1
[2022-04-24 16:48:53,124] {local_task_job.py:264} INFO - 0 downstream tasks scheduled from follow-on schedule check
