[2022-04-20 02:37:41,342] {taskinstance.py:1037} INFO - Dependencies all met for <TaskInstance: upload_to_drive.create_file scheduled__2021-02-10T00:00:00+00:00 [queued]>
[2022-04-20 02:37:41,661] {taskinstance.py:1037} INFO - Dependencies all met for <TaskInstance: upload_to_drive.create_file scheduled__2021-02-10T00:00:00+00:00 [queued]>
[2022-04-20 02:37:41,760] {taskinstance.py:1243} INFO - 
--------------------------------------------------------------------------------
[2022-04-20 02:37:41,768] {taskinstance.py:1244} INFO - Starting attempt 1 of 1
[2022-04-20 02:37:41,779] {taskinstance.py:1245} INFO - 
--------------------------------------------------------------------------------
[2022-04-20 02:37:41,976] {taskinstance.py:1264} INFO - Executing <Task(BashOperator): create_file> on 2021-02-10 00:00:00+00:00
[2022-04-20 02:37:42,070] {standard_task_runner.py:52} INFO - Started process 422 to run task
[2022-04-20 02:37:42,198] {standard_task_runner.py:76} INFO - Running: ['***', 'tasks', 'run', 'upload_to_drive', 'create_file', 'scheduled__2021-02-10T00:00:00+00:00', '--job-id', '14', '--raw', '--subdir', 'DAGS_FOLDER/upload_to_drive_dag.py', '--cfg-path', '/tmp/tmpuotpb1i8', '--error-file', '/tmp/tmpkfiy9h3q']
[2022-04-20 02:37:42,365] {standard_task_runner.py:77} INFO - Job 14: Subtask create_file
[2022-04-20 02:37:47,882] {logging_mixin.py:109} INFO - Running <TaskInstance: upload_to_drive.create_file scheduled__2021-02-10T00:00:00+00:00 [running]> on host 63b7d313710a
[2022-04-20 02:37:53,426] {taskinstance.py:1431} INFO - Exporting the following env vars:
AIRFLOW_CTX_DAG_OWNER=***
AIRFLOW_CTX_DAG_ID=upload_to_drive
AIRFLOW_CTX_TASK_ID=create_file
AIRFLOW_CTX_EXECUTION_DATE=2021-02-10T00:00:00+00:00
AIRFLOW_CTX_DAG_RUN_ID=scheduled__2021-02-10T00:00:00+00:00
[2022-04-20 02:37:53,810] {subprocess.py:62} INFO - Tmp dir root location: 
 /tmp
[2022-04-20 02:37:53,844] {subprocess.py:74} INFO - Running command: ['bash', '-c', 'echo file created on 2021-02-10. > ${AIRFLOW_HOME}/tmp/my_file_2021-02-10.txt']
[2022-04-20 02:37:54,581] {subprocess.py:85} INFO - Output:
[2022-04-20 02:37:54,733] {subprocess.py:89} INFO - bash: /opt/***/tmp/my_file_2021-02-10.txt: No such file or directory
[2022-04-20 02:37:55,651] {subprocess.py:93} INFO - Command exited with return code 1
[2022-04-20 02:37:55,902] {taskinstance.py:1718} ERROR - Task failed with exception
Traceback (most recent call last):
  File "/home/airflow/.local/lib/python3.7/site-packages/airflow/models/taskinstance.py", line 1334, in _run_raw_task
    self._execute_task_with_callbacks(context)
  File "/home/airflow/.local/lib/python3.7/site-packages/airflow/models/taskinstance.py", line 1460, in _execute_task_with_callbacks
    result = self._execute_task(context, self.task)
  File "/home/airflow/.local/lib/python3.7/site-packages/airflow/models/taskinstance.py", line 1516, in _execute_task
    result = execute_callable(context=context)
  File "/home/airflow/.local/lib/python3.7/site-packages/airflow/operators/bash.py", line 188, in execute
    f'Bash command failed. The command returned a non-zero exit code {result.exit_code}.'
airflow.exceptions.AirflowException: Bash command failed. The command returned a non-zero exit code 1.
[2022-04-20 02:37:56,817] {taskinstance.py:1282} INFO - Marking task as FAILED. dag_id=upload_to_drive, task_id=create_file, execution_date=20210210T000000, start_date=20220420T023741, end_date=20220420T023756
[2022-04-20 02:37:59,811] {standard_task_runner.py:92} ERROR - Failed to execute job 14 for task create_file
Traceback (most recent call last):
  File "/home/airflow/.local/lib/python3.7/site-packages/airflow/task/task_runner/standard_task_runner.py", line 85, in _start_by_fork
    args.func(args, dag=self.dag)
  File "/home/airflow/.local/lib/python3.7/site-packages/airflow/cli/cli_parser.py", line 48, in command
    return func(*args, **kwargs)
  File "/home/airflow/.local/lib/python3.7/site-packages/airflow/utils/cli.py", line 92, in wrapper
    return f(*args, **kwargs)
  File "/home/airflow/.local/lib/python3.7/site-packages/airflow/cli/commands/task_command.py", line 298, in task_run
    _run_task_by_selected_method(args, dag, ti)
  File "/home/airflow/.local/lib/python3.7/site-packages/airflow/cli/commands/task_command.py", line 107, in _run_task_by_selected_method
    _run_raw_task(args, ti)
  File "/home/airflow/.local/lib/python3.7/site-packages/airflow/cli/commands/task_command.py", line 184, in _run_raw_task
    error_file=args.error_file,
  File "/home/airflow/.local/lib/python3.7/site-packages/airflow/utils/session.py", line 70, in wrapper
    return func(*args, session=session, **kwargs)
  File "/home/airflow/.local/lib/python3.7/site-packages/airflow/models/taskinstance.py", line 1334, in _run_raw_task
    self._execute_task_with_callbacks(context)
  File "/home/airflow/.local/lib/python3.7/site-packages/airflow/models/taskinstance.py", line 1460, in _execute_task_with_callbacks
    result = self._execute_task(context, self.task)
  File "/home/airflow/.local/lib/python3.7/site-packages/airflow/models/taskinstance.py", line 1516, in _execute_task
    result = execute_callable(context=context)
  File "/home/airflow/.local/lib/python3.7/site-packages/airflow/operators/bash.py", line 188, in execute
    f'Bash command failed. The command returned a non-zero exit code {result.exit_code}.'
airflow.exceptions.AirflowException: Bash command failed. The command returned a non-zero exit code 1.
[2022-04-20 02:38:01,613] {local_task_job.py:154} INFO - Task exited with return code 1
[2022-04-20 02:38:07,026] {local_task_job.py:264} INFO - 0 downstream tasks scheduled from follow-on schedule check
